#VRML_SIM R2023b utf8

IMPORTABLE EXTERNPROTO "https://raw.githubusercontent.com/cyberbotics/webots/R2023b/projects/objects/solids/protos/SolidBox.proto"
EXTERNPROTO "https://raw.githubusercontent.com/cyberbotics/webots/R2022b/projects/objects/backgrounds/protos/TexturedBackground.proto"
EXTERNPROTO "https://raw.githubusercontent.com/cyberbotics/webots/R2022b/projects/objects/backgrounds/protos/TexturedBackgroundLight.proto"
EXTERNPROTO "https://raw.githubusercontent.com/cyberbotics/webots/R2023b/projects/objects/floors/protos/Floor.proto"
EXTERNPROTO "https://raw.githubusercontent.com/cyberbotics/webots/R2023b/projects/objects/factory/conveyors/protos/ConveyorBelt.proto"
EXTERNPROTO "https://raw.githubusercontent.com/cyberbotics/webots/R2023b/projects/robots/franka_emika/panda/protos/Panda.proto"
EXTERNPROTO "https://raw.githubusercontent.com/cyberbotics/webots/R2023b/projects/robots/franka_emika/panda/protos/PandaHand.proto"
EXTERNPROTO "https://raw.githubusercontent.com/cyberbotics/webots/R2023b/projects/appearances/protos/Parquetry.proto"
EXTERNPROTO "https://raw.githubusercontent.com/cyberbotics/webots/R2023b/projects/objects/factory/containers/protos/PlasticCrate.proto"
EXTERNPROTO "https://raw.githubusercontent.com/cyberbotics/webots/R2023b/projects/objects/drinks/protos/Can.proto"
EXTERNPROTO "https://raw.githubusercontent.com/cyberbotics/webots/R2023b/projects/objects/hospital/protos/HandSanitizer.proto"
EXTERNPROTO "https://raw.githubusercontent.com/cyberbotics/webots/R2023b/projects/objects/factory/pipes/protos/LJoint.proto"
EXTERNPROTO "https://raw.githubusercontent.com/cyberbotics/webots/R2023b/projects/objects/fruits/protos/Orange.proto"
EXTERNPROTO "https://raw.githubusercontent.com/cyberbotics/webots/R2023b/projects/objects/factory/forklift/protos/Forklift.proto"
EXTERNPROTO "https://raw.githubusercontent.com/cyberbotics/webots/R2023b/projects/objects/factory/fire_extinguisher/protos/FireExtinguisher.proto"

WorldInfo {
}
Viewpoint {
  orientation 0.2882470132797956 0.10657321429427674 -0.9516069615814416 2.4651140020970246
  position 6.1020557360494925 4.093656479596945 5.231538999707302
}
TexturedBackground {
}
TexturedBackgroundLight {
}
Floor {
  appearance Parquetry {
    type "light strip"
    colorOverride 0.141176 0 0.211765
  }
}
FireExtinguisher {
  translation 2.04 -4.5 0
}
LJoint {
  translation -4.01 0 1.18
  scale 6 6 6
}
PlasticCrate {
  translation 1.95 -0.77 0
  name "crate_blue"
  size 0.5 0.5 0.2
}
PlasticCrate {
  translation 1.39 -1.18 0
  name "crate_cyan"
  size 0.5 0.5 0.2
}
PlasticCrate {
  translation 0.8 -0.77 0
  name "crate_green"
  size 0.5 0.5 0.2
}
ConveyorBelt {
  translation -0.5 0 -0.47
  size 6 0.5 0.6
  speed 0.1
}
Panda {
  translation 1.38 -0.559997 0.04
  rotation 0 0 1 1.5708
  name "Panda"
  controller "<extern>"
  supervisor TRUE
  endEffectorSlot [
    DEF GRIPPER PandaHand {
    }
    Camera {
      translation 0 0 0.1
      rotation 0 1 0 -1.5707996938995747
      fieldOfView 0.3
      far 0.4
    }
    DistanceSensor {
      translation 0 0 0.6
      rotation 0 1 0 1.5708
      name "panda_distance_sensor"
      lookupTable [
        0 4095 0
        0.5 100 0
        0.51 0 0
      ]
      type "infra-red"
    }
  ]
}
Robot {
  translation 1.36 -2.4 0
  rotation 0 0 1 0.785398
  children [
    HingeJoint {
      jointParameters HingeJointParameters {
        axis 0 1 0
        anchor 0 0 0.025
      }
      device [
        RotationalMotor {
          name "left wheel motor"
        }
      ]
      endPoint Solid {
        translation 0 0.045 0.025
        rotation 0 1 0 0
        children [
          DEF WHEEL Pose {
            rotation 1 0 0 1.5707996938995747
            children [
              Shape {
                appearance PBRAppearance {
                  baseColor 1 0 0
                  roughness 1
                  metalness 0
                }
                geometry Cylinder {
                  height 0.01
                  radius 0.025
                }
              }
            ]
          }
        ]
        name "left wheel"
        boundingObject USE WHEEL
        physics Physics {
        }
      }
    }
    HingeJoint {
      jointParameters HingeJointParameters {
        axis 0 1 0
        anchor 0 0 0.025
      }
      device [
        RotationalMotor {
          name "right wheel motor"
        }
      ]
      endPoint Solid {
        translation 0 -0.045 0.025
        rotation 0 1 0 0
        children [
          USE WHEEL
        ]
        name "right wheel"
        boundingObject USE WHEEL
        physics Physics {
        }
      }
    }
    Pose {
      translation 0 0 0.0415
      children [
        Shape {
          appearance PBRAppearance {
            baseColor 0 0 1
            roughness 1
            metalness 0
          }
          geometry DEF BODY Cylinder {
            height 0.08
            radius 0.045
          }
        }
      ]
    }
    DistanceSensor {
      translation 0.042 0.02 0.063
      rotation 0 0 1 0.5236003061004253
      children [
        DEF SENSOR Pose {
          rotation 0 1 0 1.5708
          children [
            Shape {
              appearance PBRAppearance {
                baseColor 1 1 0
                roughness 1
                metalness 0
              }
              geometry Cylinder {
                height 0.004
                radius 0.008
              }
            }
          ]
        }
      ]
      name "ds0"
      lookupTable [
        0 1020 0
        0.05 1020 0
        0.15 0 0
      ]
      numberOfRays 2
      aperture 1
    }
    DistanceSensor {
      translation 0 0 0.05
      name "gps"
    }
  ]
  name "rover"
  boundingObject Pose {
    translation 0 0 0.0415
    children [
      USE BODY
    ]
  }
  physics Physics {
  }
  controller "<extern>"
}
PlasticCrate {
  translation 1.18 -4.59 0
  size 0.9 0.7 0.2
  color 0.3 0.3 0.2
}
Can {
  translation 1.53 -4.84 0.06
}
HandSanitizer {
  translation 1.08804 -4.81 0.0312533
  rotation 0.3853919091257548 0.732068827380387 -0.5617368675441475 -2.0499353071795863
}
Orange {
  translation 0.94 -4.57 0.05
}
Forklift {
  translation -3.7 -3.96 0.81
  enablePhysics FALSE
}
